Workbook
Name 業績関連目標: TBL!$N$4:$N$6
Name 個人重点施策: TBL!$N$7:$N$10
Name 人材関連目標: TBL!$N$11:$N$14

Sheet ②評価シート（C）
A1: 評価シート（契約社員用） | AD1: 本人記入欄
A2: 評価時期 | C2: 2025 | E2: 下期 | Y2: 成果評価点 | AA2: 行動評価点 | AD2: 上司記入欄
A3: 社員番号 | C3: K2505812 | E3: 氏名 | G3: 菅原 崇明 | J3: 組織区分 | L3: DEC | O3: 役割区分 | Q3: リーダー/チーフ/SV | Y3: =IF(AB23=0,"-",AB23) -> - | AA3: =AB52 -> - | AD3: 自動計算欄
A4: 入社日 | C4: 45870 | E4: 所属 | G4: CX事業統括 デジタルカスタマーコミュニケーション総括 東北サービス統括部 三課 NGH
A6: ■1次評価者 面談実施確認欄
E7: 1次評価者社員番号 | H7: 1次評価者氏名 | N7: 日時 | U7: 面談場所
A8: 目標設定面談 | E8: k1811087 | H8: 村越 弓子 | N8: 11 | O8: 月 | P8: 6 | Q8: 日 | R8: 0.75 | S8: ~ | T8: 0.77083333 | U8: 研修室
A9: 評価面談 | N9: 4 | O9: 月 | P9: 17 | Q9: 日 | S9: ~
A11: ■成果評価シート
R13: =1-$Q$22 -> 0
A14: 目標内容 | Q14: 難易度 | R14: ウェイト | S14: 自己評価 | W14: 上司評価 | AB14: ウェイト × 評価点
A15: 何を | F15: いつまでに | G15: どのくらい | L15: どのように（プロセス） | S15: 達成度 | T15: 自己レビュー | W15: 達成度 | X15: 上司コメント | AA15: 評価点 | AE15: ウェイトCK | AF15: 未入力CK | AG15: 上司評価CK
A16: トラブル防止 | F16: 3月末 | G16: 重度・中重度・中度・軽度 4大トラブル0件 | L16: ・スプリングの取り扱いについて、バッグではなくセキュリティカード側に取付されていないか日頃から目を配り、セキュリティカードについていることを確認した場合は、即時バッグへ取付させる ・セキュリティカードの紛失や盗難、誤廃棄を防止するために月一で取り扱いに関する確認を実施 | Q16: B | R16: 0.2 | S16: Ⅲ | T16: マンスリーチェックの時の声掛けと目視確認の実施にて未然に防止し、トラブル発生0件達成。 | AA16: =IF(COUNTA(Q16,R16,W16)=3,VLOOKUP(Q16&W16,TBL!F:G,2,0),"") | AB16: =IF(AND(AE16="OK",AA16<>""),R16*AA16,"") | AC16: =IF(AD16<>"","←","") -> ← | AD16: =IF(COUNTA(A16:R16)=0,"",IF(COUNTIF(AE16:AG16,"OK")=3,"OK",IF(COUNTIF(AE16:AF16,"OK")=2,"・目標設定OK"&CHAR(10)&AG16,IF(AE16="OK",AF16,IF(AF16="OK",AE16,AF16&CHAR(10)&AE16))))) -> ・目標設定OK ・上司評価未入力 | AE16: =IF(COUNTA(A16:R16)<>0,IF($Q$22<>1,"・ウェイト確認","OK"),"-") -> OK | AF16: =IF(COUNTA(A16:R16)<>0,IF(COUNTA(A16:R16)<>6,"・未入力項目あり","OK"),"-") -> OK | AG16: =IF(AF16="OK",IF(W16<>"","OK","・上司評価未入力"),"-") -> ・上司評価未入力
A17: 離職率 | F17: 3月末 | G17: 11月から3月末まで各月の離職率を5％以下にする | L17: ・勤怠の乱れや、長時間対応が発生したCMに対し、メンタルケアの面談を実施する。 ・面談の結果をSVへ報告し、CMの不満点を改善するための施策を考える。 ・SVへ報告後の状況を含め、該当のCMへ経過確認の面談を実施する。 | Q17: A | R17: 0.2 | S17: Ⅰ | T17: 異動/ヘルプ 19名 契約満了 24名 中途退職 24名 在籍 43名 となり目標未達。 | AA17: =IF(COUNTA(Q17,R17,W17)=3,VLOOKUP(Q17&W17,TBL!F:G,2,0),"") | AB17: =IF(AND(AE17="OK",AA17<>""),R17*AA17,"") | AC17: =IF(AD17<>"","←","") -> ← | AD17: =IF(COUNTA(A17:R17)=0,"",IF(COUNTIF(AE17:AG17,"OK")=3,"OK",IF(COUNTIF(AE17:AF17,"OK")=2,"・目標設定OK"&CHAR(10)&AG17,IF(AE17="OK",AF17,IF(AF17="OK",AE17,AF17&CHAR(10)&AE17))))) -> ・目標設定OK ・上司評価未入力 | AE17: =IF(COUNTA(A17:R17)<>0,IF($Q$22<>1,"・ウェイト確認","OK"),"-") -> OK | AF17: =IF(COUNTA(A17:R17)<>0,IF(COUNTA(A17:R17)<>6,"・未入力項目あり","OK"),"-") -> OK | AG17: =IF(AF17="OK",IF(W17<>"","OK","・上司評価未入力"),"-") -> ・上司評価未入力
A18: メンバーの育成・指導 | F18: 3月末 | G18: ATTを各月で最低30秒短縮し、3月末時点で10分にする | L18: ・ATTが超過傾向にあるCMを５名選出 ・要因の分析や実際にATTが短いCMからの意見を基にその対策を考え、対象者へ共有 ・施策がATT短縮へ繋がった場合は、全Mへ共有 ・ATT10分を超えたコールはリアモニし、ATT短縮を図る | Q18: B | R18: 0.2 | S18: Ⅱ | T18: 11月 15分05秒 12月 14分00秒（-65秒） 1月 12分52秒（-68秒） 2月 13分05秒（+13秒） 3月 12分53秒（-12秒） 各月の目標としては未達だが、 施策の実施にて11月のATTから-132秒の短縮に成功した。 | AA18: =IF(COUNTA(Q18,R18,W18)=3,VLOOKUP(Q18&W18,TBL!F:G,2,0),"") | AB18: =IF(AND(AE18="OK",AA18<>""),R18*AA18,"") | AC18: =IF(AD18<>"","←","") -> ← | AD18: =IF(COUNTA(A18:R18)=0,"",IF(COUNTIF(AE18:AG18,"OK")=3,"OK",IF(COUNTIF(AE18:AF18,"OK")=2,"・目標設定OK"&CHAR(10)&AG18,IF(AE18="OK",AF18,IF(AF18="OK",AE18,AF18&CHAR(10)&AE18))))) -> ・目標設定OK ・上司評価未入力 | AE18: =IF(COUNTA(A18:R18)<>0,IF($Q$22<>1,"・ウェイト確認","OK"),"-") -> OK | AF18: =IF(COUNTA(A18:R18)<>0,IF(COUNTA(A18:R18)<>6,"・未入力項目あり","OK"),"-") -> OK | AG18: =IF(AF18="OK",IF(W18<>"","OK","・上司評価未入力"),"-") -> ・上司評価未入力
A19: 研修時間/受講数 | F19: 3月末 | G19: 外部研修2件受講 | L19: ・SVへの昇格を目指し、現場を円滑に稼働させるためのスキルや、CMのスキルアップをサポートに繋げられる研修の申し込みと受講を実施する | Q19: B | R19: 0.2 | S19: Ⅰ | T19: 外部研修受講0件のため未達。 | AA19: =IF(COUNTA(Q19,R19,W19)=3,VLOOKUP(Q19&W19,TBL!F:G,2,0),"") | AB19: =IF(AND(AE19="OK",AA19<>""),R19*AA19,"") | AC19: =IF(AD19<>"","←","") -> ← | AD19: =IF(COUNTA(A19:R19)=0,"",IF(COUNTIF(AE19:AG19,"OK")=3,"OK",IF(COUNTIF(AE19:AF19,"OK")=2,"・目標設定OK"&CHAR(10)&AG19,IF(AE19="OK",AF19,IF(AF19="OK",AE19,AF19&CHAR(10)&AE19))))) -> ・目標設定OK ・上司評価未入力 | AE19: =IF(COUNTA(A19:R19)<>0,IF($Q$22<>1,"・ウェイト確認","OK"),"-") -> OK | AF19: =IF(COUNTA(A19:R19)<>0,IF(COUNTA(A19:R19)<>6,"・未入力項目あり","OK"),"-") -> OK | AG19: =IF(AF19="OK",IF(W19<>"","OK","・上司評価未入力"),"-") -> ・上司評価未入力
A20: 資格取得 | F20: 12月末 | G20: ・MCF認定の取得 ・ケーブル認定の取得 | L20: ・ランダムで1日2～3名のリアモニを実施 ・応対品質チェックフォームを活用し、現場状況をみてFBまで実施する ・自己学習の時間を確保する | Q20: B | R20: 0.2 | S20: Ⅰ | T20: MCF認定：未 ケーブル認定：4月合格 進捗管理が甘く、自己学習の時間を確保できていなかった。 | AA20: =IF(COUNTA(Q20,R20,W20)=3,VLOOKUP(Q20&W20,TBL!F:G,2,0),"") | AB20: =IF(AND(AE20="OK",AA20<>""),R20*AA20,"") | AC20: =IF(AD20<>"","←","") -> ← | AD20: =IF(COUNTA(A20:R20)=0,"",IF(COUNTIF(AE20:AG20,"OK")=3,"OK",IF(COUNTIF(AE20:AF20,"OK")=2,"・目標設定OK"&CHAR(10)&AG20,IF(AE20="OK",AF20,IF(AF20="OK",AE20,AF20&CHAR(10)&AE20))))) -> ・目標設定OK ・上司評価未入力 | AE20: =IF(COUNTA(A20:R20)<>0,IF($Q$22<>1,"・ウェイト確認","OK"),"-") -> OK | AF20: =IF(COUNTA(A20:R20)<>0,IF(COUNTA(A20:R20)<>6,"・未入力項目あり","OK"),"-") -> OK | AG20: =IF(AF20="OK",IF(W20<>"","OK","・上司評価未入力"),"-") -> ・上司評価未入力
AA21: =IF(COUNTA(Q21,R21,W21)=3,VLOOKUP(Q21&W21,TBL!F:G,2,0),"") | AB21: =IF(AND(AE21="OK",AA21<>""),R21*AA21,"") | AC21: =IF(AD21<>"","←","") | AD21: =IF(COUNTA(A21:R21)=0,"",IF(COUNTIF(AE21:AG21,"OK")=3,"OK",IF(COUNTIF(AE21:AF21,"OK")=2,"・目標設定OK"&CHAR(10)&AG21,IF(AE21="OK",AF21,IF(AF21="OK",AE21,AF21&CHAR(10)&AE21))))) | AE21: =IF(COUNTA(A21:R21)<>0,IF($Q$22<>1,"・ウェイト確認","OK"),"-") -> - | AF21: =IF(COUNTA(A21:R21)<>0,IF(COUNTA(A21:R21)<>6,"・未入力項目あり","OK"),"-") -> - | AG21: =IF(AF21="OK",IF(W21<>"","OK","・上司評価未入力"),"-") -> -
Q22: =SUM(R16:R21) -> 1
X23: 成果評価点 | AB23: =IF(COUNT(AB16:AB21)=COUNTIF(AE13:AE21,"OK"),SUM(AB16:AB21),"-") -> -
X24: ■評価点
A25: 難易度 | B25: 定義 | J25: 達成度 | K25: 達成目安 | X25: 難易度 達成度 | Y25: S | Z25: A | AA25: B | AB25: C
A26: S | B26: 上司、上位職に求められるレベルの目標 | J26: Ⅴ | K26: 設定目標を大きく上回り、突出した成果を出した | R26: 130％以上 | X26: Ⅴ | Y26: 80 | Z26: 70 | AA26: 55 | AB26: 45
A27: A | B27: 自身の経験・能力の範疇よりストレッチした目標 | J27: Ⅳ | K27: 設定目標を上回り、期待を超える成果を出した | R27: 110％以上～130％未満 | X27: Ⅳ | Y27: 65 | Z27: 55 | AA27: 45 | AB27: 35
A28: B | B28: 過去の経験・能力の範疇で達成可能な目標 | J28: Ⅲ | K28: 設定目標を満たした | R28: 100％以上～110％未満 | X28: Ⅲ | Y28: 55 | Z28: 45 | AA28: 35 | AB28: 25
A29: C | B29: 部下、下位職に求められるレベルの目標 | J29: Ⅱ | K29: 設定目標に一歩及ばず、成果を一部達成できなかった | R29: 80％以上～100％未満 | X29: Ⅱ | Y29: 40 | Z29: 30 | AA29: 25 | AB29: 15
J30: Ⅰ | K30: 設定目標を大きく下回り、成果を達成できなかった | R30: 80％未満 | X30: Ⅰ | Y30: 25 | Z30: 15 | AA30: 10 | AB30: 1
A32: ■行動評価シート
A34: 行動評価項目 | G34: 期待行動 | T34: 自己評価 （期末） | X34: 上司評価 （期末）
T35: 達成度 | U35: 自己レビュー | X35: 達成度 | Y35: 上司コメント | AB35: 評価点 | AE35: 自己評価CK | AF35: 上司評価CK
A36: 事業所のTCIP | B36: T（Trust）信頼 | G36: =IF($Q$3="","",VLOOKUP(B36,①行動評価項目!B:G,VLOOKUP($Q$3,TBL!I:J,2,0),0)) -> 通り一辺倒な質疑応答ではなく対話者の状況を正しくヒアリングし、ひとりひとりの状況に合わせた案内を行います | T36: Ⅲ | U36: 自身がお客様対応をしているという前提のもと、問題点の整理や知識向上に勤めCMのエスカレーション対応を行うことで、意識的にお客様とCM双方へのわかりやすい説明ができていたと感じる。 | AB36: =IF(X36<>"",VLOOKUP(X36,TBL!Q:R,2,0),"") | AC36: =IF(AD36<>"","←","") -> ← | AD36: =IF(G36="","",IF(AND(AE36="OK",AF36="OK"),"OK",IF(AE36="OK",AF36,IF(AF36="OK",AE36,AE36&CHAR(10)&AF36)))) -> ・上司評価未入力 | AE36: =IF(G36="","-",IF(T36<>"","OK","・自己評価未入力")) -> OK | AF36: =IF(G36="","-",IF(X36<>"","OK","・上司評価未入力")) -> ・上司評価未入力
B37: C（Contribution）貢献 | G37: =IF($Q$3="","",VLOOKUP(B37,①行動評価項目!B:G,VLOOKUP($Q$3,TBL!I:J,2,0),0)) -> 対話者の方のお困りごとがなぜ起こったのか？を汲み取り改善につながる声を拾います | T37: Ⅲ | AB37: =IF(X37<>"",VLOOKUP(X37,TBL!Q:R,2,0),"") | AC37: =IF(AD37<>"","←","") -> ← | AD37: =IF(G37="","",IF(AND(AE37="OK",AF37="OK"),"OK",IF(AE37="OK",AF37,IF(AF37="OK",AE37,AE37&CHAR(10)&AF37)))) -> ・上司評価未入力 | AE37: =IF(G37="","-",IF(T37<>"","OK","・自己評価未入力")) -> OK | AF37: =IF(G37="","-",IF(X37<>"","OK","・上司評価未入力")) -> ・上司評価未入力
B38: I（Improvement）成長 | G38: =IF($Q$3="","",VLOOKUP(B38,①行動評価項目!B:G,VLOOKUP($Q$3,TBL!I:J,2,0),0)) -> 変化していく環境にあわせプロフェッショナルとして「よりよい案内とは？」を考え成長していきます | T38: Ⅲ | AB38: =IF(X38<>"",VLOOKUP(X38,TBL!Q:R,2,0),"") | AC38: =IF(AD38<>"","←","") -> ← | AD38: =IF(G38="","",IF(AND(AE38="OK",AF38="OK"),"OK",IF(AE38="OK",AF38,IF(AF38="OK",AE38,AE38&CHAR(10)&AF38)))) -> ・上司評価未入力 | AE38: =IF(G38="","-",IF(T38<>"","OK","・自己評価未入力")) -> OK | AF38: =IF(G38="","-",IF(X38<>"","OK","・上司評価未入力")) -> ・上司評価未入力
B39: P（People）ヒト | G39: =IF($Q$3="","",VLOOKUP(B39,①行動評価項目!B:G,VLOOKUP($Q$3,TBL!I:J,2,0),0)) -> 対話者の方への配慮を第一に、わかりやすい速度・表現での案内とともに人ならではの対話を行います | T39: Ⅲ | AB39: =IF(X39<>"",VLOOKUP(X39,TBL!Q:R,2,0),"") | AC39: =IF(AD39<>"","←","") -> ← | AD39: =IF(G39="","",IF(AND(AE39="OK",AF39="OK"),"OK",IF(AE39="OK",AF39,IF(AF39="OK",AE39,AE39&CHAR(10)&AF39)))) -> ・上司評価未入力 | AE39: =IF(G39="","-",IF(T39<>"","OK","・自己評価未入力")) -> OK | AF39: =IF(G39="","-",IF(X39<>"","OK","・上司評価未入力")) -> ・上司評価未入力
A40: 変化に対する期待行動 | B40: =①行動評価項目!B8 -> 情報収集 | G40: =IF($Q$3="","",VLOOKUP(B40,①行動評価項目!B:G,VLOOKUP($Q$3,TBL!I:J,2,0),0)) -> 自部門のサービス・業務に対し、業務レベルでの理解があり、関連する最新の業界動向や顧客情報、競合他社情報などを幅広く収集して、業務に活用している。 | T40: Ⅲ | AB40: =IF(X40<>"",VLOOKUP(X40,TBL!Q:R,2,0),"") | AC40: =IF(AD40<>"","←","") -> ← | AD40: =IF(G40="","",IF(AND(AE40="OK",AF40="OK"),"OK",IF(AE40="OK",AF40,IF(AF40="OK",AE40,AE40&CHAR(10)&AF40)))) -> ・上司評価未入力 | AE40: =IF(G40="","-",IF(T40<>"","OK","・自己評価未入力")) -> OK | AF40: =IF(G40="","-",IF(X40<>"","OK","・上司評価未入力")) -> ・上司評価未入力
B41: =①行動評価項目!B9 -> 課題認識・企画提案 | G41: =IF($Q$3="","",VLOOKUP(B41,①行動評価項目!B:G,VLOOKUP($Q$3,TBL!I:J,2,0),0)) -> 業務上の問題点を整理し、状況、状態を的確に把握すると共に、状況変化に応じて業務の優先順位をつけて、対応策を検討している。 | T41: Ⅲ | AB41: =IF(X41<>"",VLOOKUP(X41,TBL!Q:R,2,0),"") | AC41: =IF(AD41<>"","←","") -> ← | AD41: =IF(G41="","",IF(AND(AE41="OK",AF41="OK"),"OK",IF(AE41="OK",AF41,IF(AF41="OK",AE41,AE41&CHAR(10)&AF41)))) -> ・上司評価未入力 | AE41: =IF(G41="","-",IF(T41<>"","OK","・自己評価未入力")) -> OK | AF41: =IF(G41="","-",IF(X41<>"","OK","・上司評価未入力")) -> ・上司評価未入力
B42: =①行動評価項目!B10 -> 適応・柔軟性 | G42: =IF($Q$3="","",VLOOKUP(B42,①行動評価項目!B:G,VLOOKUP($Q$3,TBL!I:J,2,0),0)) -> 環境や状況の変化を察知し、上位方針や過去の事例に基づいて適切に判断している。 | T42: Ⅲ | AB42: =IF(X42<>"",VLOOKUP(X42,TBL!Q:R,2,0),"") | AC42: =IF(AD42<>"","←","") -> ← | AD42: =IF(G42="","",IF(AND(AE42="OK",AF42="OK"),"OK",IF(AE42="OK",AF42,IF(AF42="OK",AE42,AE42&CHAR(10)&AF42)))) -> ・上司評価未入力 | AE42: =IF(G42="","-",IF(T42<>"","OK","・自己評価未入力")) -> OK | AF42: =IF(G42="","-",IF(X42<>"","OK","・上司評価未入力")) -> ・上司評価未入力
A43: 顧客に対する期待行動 | B43: =①行動評価項目!B11 -> 信頼構築 | G43: =IF($Q$3="","",VLOOKUP(B43,①行動評価項目!B:G,VLOOKUP($Q$3,TBL!I:J,2,0),0)) -> 現場を大切にして、顧客の利益につながるよう、特に指示がなくとも求められている使命を果たすよう行動し、自身への信頼を獲得している | T43: Ⅲ | AB43: =IF(X43<>"",VLOOKUP(X43,TBL!Q:R,2,0),"") | AC43: =IF(AD43<>"","←","") -> ← | AD43: =IF(G43="","",IF(AND(AE43="OK",AF43="OK"),"OK",IF(AE43="OK",AF43,IF(AF43="OK",AE43,AE43&CHAR(10)&AF43)))) -> ・上司評価未入力 | AE43: =IF(G43="","-",IF(T43<>"","OK","・自己評価未入力")) -> OK | AF43: =IF(G43="","-",IF(X43<>"","OK","・上司評価未入力")) -> ・上司評価未入力
B44: =①行動評価項目!B12 -> サービス改善・創意工夫 | G44: =IF($Q$3="","",VLOOKUP(B44,①行動評価項目!B:G,VLOOKUP($Q$3,TBL!I:J,2,0),0)) -> 顧客のより高い満足を実現するために、提供サービスや業務に創意工夫や改善を行ない、チーム全体で顧客の期待以上の品質向上や効率化に取り組んでいる。 | T44: Ⅲ | AB44: =IF(X44<>"",VLOOKUP(X44,TBL!Q:R,2,0),"") | AC44: =IF(AD44<>"","←","") -> ← | AD44: =IF(G44="","",IF(AND(AE44="OK",AF44="OK"),"OK",IF(AE44="OK",AF44,IF(AF44="OK",AE44,AE44&CHAR(10)&AF44)))) -> ・上司評価未入力 | AE44: =IF(G44="","-",IF(T44<>"","OK","・自己評価未入力")) -> OK | AF44: =IF(G44="","-",IF(X44<>"","OK","・上司評価未入力")) -> ・上司評価未入力
A45: 組織に対する期待行動 | B45: =①行動評価項目!B13 -> 役割認識・リーダーシップ | G45: =IF($Q$3="","",VLOOKUP(B45,①行動評価項目!B:G,VLOOKUP($Q$3,TBL!I:J,2,0),0)) -> 組織目標や上位方針から、自身の果たすべき役割や責任を正しく認識し、迅速な行動・判断によってリーダーシップを発揮し、チームに貢献している。 | T45: Ⅲ | AB45: =IF(X45<>"",VLOOKUP(X45,TBL!Q:R,2,0),"") | AC45: =IF(AD45<>"","←","") -> ← | AD45: =IF(G45="","",IF(AND(AE45="OK",AF45="OK"),"OK",IF(AE45="OK",AF45,IF(AF45="OK",AE45,AE45&CHAR(10)&AF45)))) -> ・上司評価未入力 | AE45: =IF(G45="","-",IF(T45<>"","OK","・自己評価未入力")) -> OK | AF45: =IF(G45="","-",IF(X45<>"","OK","・上司評価未入力")) -> ・上司評価未入力
...

Sheet 記入サンプル
A1: 評価シート（契約社員用） | AD1: 本人記入欄
A2: 評価時期 | C2: 2017年度 | E2: 上期 | Y2: 成果評価点 | AA2: 行動評価点 | AD2: 上司記入欄
A3: 社員番号 | C3: XXXXXXX | E3: 氏名 | G3: XXXXXXX | J3: 組織区分 | L3: 本社 | O3: 役割区分 | Q3: リーダー/チーフ/SV | Y3: =IF(AB23=0,"-",AB23) -> 43 | AA3: =AB52 -> 45 | AD3: 自動計算欄
A4: 入社日 | C4: XXXX/XX/XX | E4: 所属 | G4: XXXXXXXXXXXXXXXXXXXXXX
A6: ■1次評価者 面談実施確認欄
E7: 1次評価者社員番号 | H7: 1次評価者氏名 | N7: 日時 | U7: 面談場所
A8: 目標設定面談 | O8: 月 | Q8: 日 | S8: ~
A9: 評価面談 | O9: 月 | Q9: 日 | S9: ~
A11: ■成果評価シート
R13: =1-$Q$22 -> 0
A14: 目標内容 | Q14: 難易度 | R14: ウェイト | S14: 自己評価 | W14: 上司評価 | AB14: ウェイト × 評価点
A15: 何を | F15: いつまでに | G15: どのくらい | L15: どのように（プロセス） | S15: 達成度 | T15: 自己レビュー | W15: 達成度 | X15: 上司コメント | AA15: 評価点 | AE15: ウェイトCK | AF15: 未入力CK | AG15: 上司評価CK
A16: 新規取り組みの実行 | F16: XXX | G16: ××の課題解決 | L16: XXXXXXXX | Q16: A | R16: 0.4 | S16: Ⅲ | W16: Ⅳ | X16: XXXXXXXX | AA16: =IF(COUNTA(Q16,R16,W16)=3,VLOOKUP(Q16&W16,TBL!F:G,2,0),"") -> 55 | AB16: =IF(AND(AE16="OK",AA16<>""),R16*AA16,"") -> 22 | AC16: =IF(AD16<>"","←","") -> ← | AD16: =IF(COUNTA(A16:R16)=0,"",IF(COUNTIF(AE16:AG16,"OK")=3,"OK",IF(COUNTIF(AE16:AF16,"OK")=2,"・目標設定OK"&CHAR(10)&AG16,IF(AE16="OK",AF16,IF(AF16="OK",AE16,AF16&CHAR(10)&AE16))))) -> OK | AE16: =IF(COUNTA(A16:R16)<>0,IF($Q$22<>1,"・ウェイト確認","OK"),"-") -> OK | AF16: =IF(COUNTA(A16:R16)<>0,IF(COUNTA(A16:R16)<>6,"・未入力項目あり","OK"),"-") -> OK | AG16: =IF(AF16="OK",IF(W16<>"","OK","・上司評価未入力"),"-") -> OK
A17: ○○業務効率化 | F17: XXX | G17: 工数○時間削減 | L17: XXXXXXXX | Q17: B | R17: 0.3 | S17: Ⅳ | W17: Ⅲ | AA17: =IF(COUNTA(Q17,R17,W17)=3,VLOOKUP(Q17&W17,TBL!F:G,2,0),"") -> 35 | AB17: =IF(AND(AE17="OK",AA17<>""),R17*AA17,"") -> 10.5 | AC17: =IF(AD17<>"","←","") -> ← | AD17: =IF(COUNTA(A17:R17)=0,"",IF(COUNTIF(AE17:AG17,"OK")=3,"OK",IF(COUNTIF(AE17:AF17,"OK")=2,"・目標設定OK"&CHAR(10)&AG17,IF(AE17="OK",AF17,IF(AF17="OK",AE17,AF17&CHAR(10)&AE17))))) -> OK | AE17: =IF(COUNTA(A17:R17)<>0,IF($Q$22<>1,"・ウェイト確認","OK"),"-") -> OK | AF17: =IF(COUNTA(A17:R17)<>0,IF(COUNTA(A17:R17)<>6,"・未入力項目あり","OK"),"-") -> OK | AG17: =IF(AF17="OK",IF(W17<>"","OK","・上司評価未入力"),"-") -> OK
A18: ○○領域の理解 | F18: XXX | G18: ○○業務について、他者に説明できるようになる | L18: XXXXXXXX | Q18: B | R18: 0.3 | S18: Ⅲ | W18: Ⅲ | AA18: =IF(COUNTA(Q18,R18,W18)=3,VLOOKUP(Q18&W18,TBL!F:G,2,0),"") -> 35 | AB18: =IF(AND(AE18="OK",AA18<>""),R18*AA18,"") -> 10.5 | AC18: =IF(AD18<>"","←","") -> ← | AD18: =IF(COUNTA(A18:R18)=0,"",IF(COUNTIF(AE18:AG18,"OK")=3,"OK",IF(COUNTIF(AE18:AF18,"OK")=2,"・目標設定OK"&CHAR(10)&AG18,IF(AE18="OK",AF18,IF(AF18="OK",AE18,AF18&CHAR(10)&AE18))))) -> OK | AE18: =IF(COUNTA(A18:R18)<>0,IF($Q$22<>1,"・ウェイト確認","OK"),"-") -> OK | AF18: =IF(COUNTA(A18:R18)<>0,IF(COUNTA(A18:R18)<>6,"・未入力項目あり","OK"),"-") -> OK | AG18: =IF(AF18="OK",IF(W18<>"","OK","・上司評価未入力"),"-") -> OK
AA19: =IF(COUNTA(Q19,R19,W19)=3,VLOOKUP(Q19&W19,TBL!F:G,2,0),"") | AB19: =IF(AND(AE19="OK",AA19<>""),R19*AA19,"") | AC19: =IF(AD19<>"","←","") | AD19: =IF(COUNTA(A19:R19)=0,"",IF(COUNTIF(AE19:AG19,"OK")=3,"OK",IF(COUNTIF(AE19:AF19,"OK")=2,"・目標設定OK"&CHAR(10)&AG19,IF(AE19="OK",AF19,IF(AF19="OK",AE19,AF19&CHAR(10)&AE19))))) | AE19: =IF(COUNTA(A19:R19)<>0,IF($Q$22<>1,"・ウェイト確認","OK"),"-") -> - | AF19: =IF(COUNTA(A19:R19)<>0,IF(COUNTA(A19:R19)<>6,"・未入力項目あり","OK"),"-") -> - | AG19: =IF(AF19="OK",IF(W19<>"","OK","・上司評価未入力"),"-") -> -
AA20: =IF(COUNTA(Q20,R20,W20)=3,VLOOKUP(Q20&W20,TBL!F:G,2,0),"") | AB20: =IF(AND(AE20="OK",AA20<>""),R20*AA20,"") | AC20: =IF(AD20<>"","←","") | AD20: =IF(COUNTA(A20:R20)=0,"",IF(COUNTIF(AE20:AG20,"OK")=3,"OK",IF(COUNTIF(AE20:AF20,"OK")=2,"・目標設定OK"&CHAR(10)&AG20,IF(AE20="OK",AF20,IF(AF20="OK",AE20,AF20&CHAR(10)&AE20))))) | AE20: =IF(COUNTA(A20:R20)<>0,IF($Q$22<>1,"・ウェイト確認","OK"),"-") -> - | AF20: =IF(COUNTA(A20:R20)<>0,IF(COUNTA(A20:R20)<>6,"・未入力項目あり","OK"),"-") -> - | AG20: =IF(AF20="OK",IF(W20<>"","OK","・上司評価未入力"),"-") -> -
AA21: =IF(COUNTA(Q21,R21,W21)=3,VLOOKUP(Q21&W21,TBL!F:G,2,0),"") | AB21: =IF(AND(AE21="OK",AA21<>""),R21*AA21,"") | AC21: =IF(AD21<>"","←","") | AD21: =IF(COUNTA(A21:R21)=0,"",IF(COUNTIF(AE21:AG21,"OK")=3,"OK",IF(COUNTIF(AE21:AF21,"OK")=2,"・目標設定OK"&CHAR(10)&AG21,IF(AE21="OK",AF21,IF(AF21="OK",AE21,AF21&CHAR(10)&AE21))))) | AE21: =IF(COUNTA(A21:R21)<>0,IF($Q$22<>1,"・ウェイト確認","OK"),"-") -> - | AF21: =IF(COUNTA(A21:R21)<>0,IF(COUNTA(A21:R21)<>6,"・未入力項目あり","OK"),"-") -> - | AG21: =IF(AF21="OK",IF(W21<>"","OK","・上司評価未入力"),"-") -> -
Q22: =SUM(R16:R21) -> 1
X23: 成果評価点 | AB23: =IF(COUNT(AB16:AB21)=COUNTIF(AE13:AE21,"OK"),SUM(AB16:AB21),"-") -> 43
X24: ■評価点
A25: 難易度 | B25: 定義 | J25: 達成度 | K25: 達成目安 | X25: 難易度 達成度 | Y25: S | Z25: A | AA25: B | AB25: C
A26: S | B26: 上司、上位職に求められるレベルの目標 | J26: Ⅴ | K26: 設定目標を大きく上回り、突出した成果を出した | R26: 130％以上 | X26: Ⅴ | Y26: 80 | Z26: 70 | AA26: 55 | AB26: 45
A27: A | B27: 自身の経験・能力の範疇よりストレッチした目標 | J27: Ⅳ | K27: 設定目標を上回り、期待を超える成果を出した | R27: 110％以上～130％未満 | X27: Ⅳ | Y27: 65 | Z27: 55 | AA27: 45 | AB27: 35
A28: B | B28: 過去の経験・能力の範疇で達成可能な目標 | J28: Ⅲ | K28: 設定目標を満たした | R28: 100％以上～110％未満 | X28: Ⅲ | Y28: 55 | Z28: 45 | AA28: 35 | AB28: 25
A29: C | B29: 部下、下位職に求められるレベルの目標 | J29: Ⅱ | K29: 設定目標に一歩及ばず、成果を一部達成できなかった | R29: 80％以上～100％未満 | X29: Ⅱ | Y29: 40 | Z29: 30 | AA29: 25 | AB29: 15
J30: Ⅰ | K30: 設定目標を大きく下回り、成果を達成できなかった | R30: 80％未満 | X30: Ⅰ | Y30: 25 | Z30: 15 | AA30: 10 | AB30: 1
A32: ■行動評価シート
A34: 行動評価項目 | G34: 期待行動 | T34: 自己評価 （期末） | X34: 上司評価 （期末）
T35: 達成度 | U35: 自己レビュー | X35: 達成度 | Y35: 上司コメント | AB35: 評価点 | AE35: 自己評価CK | AF35: 上司評価CK
A36: 変化に対する期待行動 | B36: 情報収集 | G36: 自部門のサービス・業務に対し、業務レベルでの理解があり、関連する最新の業界動向や顧客情報、競合他社情報などを幅広く収集して、業務に活用している。 | T36: Ⅲ | U36: XXXXXXXXX | X36: Ⅲ | Y36: XXXXXXXXX | AB36: =IF(X36<>"",VLOOKUP(X36,TBL!Q:R,2,0),"") -> 40 | AC36: =IF(AD36<>"","←","") -> ← | AD36: =IF(G36="","",IF(AND(AE36="OK",AF36="OK"),"OK",IF(AE36="OK",AF36,IF(AF36="OK",AE36,AE36&CHAR(10)&AF36)))) -> OK | AE36: =IF(G36="","-",IF(T36<>"","OK","・自己評価未入力")) -> OK | AF36: =IF(G36="","-",IF(X36<>"","OK","・上司評価未入力")) -> OK
B37: 課題認識・企画提案 | G37: 業務上の問題点を整理し、状況、状態を的確に把握すると共に、状況変化に応じて業務の優先順位をつけて、対応策を検討している。 | T37: Ⅲ | X37: Ⅲ | AB37: =IF(X37<>"",VLOOKUP(X37,TBL!Q:R,2,0),"") -> 40 | AC37: =IF(AD37<>"","←","") -> ← | AD37: =IF(G37="","",IF(AND(AE37="OK",AF37="OK"),"OK",IF(AE37="OK",AF37,IF(AF37="OK",AE37,AE37&CHAR(10)&AF37)))) -> OK | AE37: =IF(G37="","-",IF(T37<>"","OK","・自己評価未入力")) -> OK | AF37: =IF(G37="","-",IF(X37<>"","OK","・上司評価未入力")) -> OK
B38: 適応・柔軟性 | G38: 環境や状況の変化を察知し、上位方針や過去の事例に基づいて適切に判断している。 | T38: Ⅲ | X38: Ⅳ | AB38: =IF(X38<>"",VLOOKUP(X38,TBL!Q:R,2,0),"") -> 60 | AC38: =IF(AD38<>"","←","") -> ← | AD38: =IF(G38="","",IF(AND(AE38="OK",AF38="OK"),"OK",IF(AE38="OK",AF38,IF(AF38="OK",AE38,AE38&CHAR(10)&AF38)))) -> OK | AE38: =IF(G38="","-",IF(T38<>"","OK","・自己評価未入力")) -> OK | AF38: =IF(G38="","-",IF(X38<>"","OK","・上司評価未入力")) -> OK
A39: 顧客に対する期待行動 | B39: 顧客志向 | G39: 顧客が難しい問題に直面している時に、相手が何を求めているかを察知し、いつでも十分に対応できるよう、自発的に対応している。 | T39: Ⅲ | U39: XXXXXXXXX | X39: Ⅲ | AB39: =IF(X39<>"",VLOOKUP(X39,TBL!Q:R,2,0),"") -> 40 | AC39: =IF(AD39<>"","←","") -> ← | AD39: =IF(G39="","",IF(AND(AE39="OK",AF39="OK"),"OK",IF(AE39="OK",AF39,IF(AF39="OK",AE39,AE39&CHAR(10)&AF39)))) -> OK | AE39: =IF(G39="","-",IF(T39<>"","OK","・自己評価未入力")) -> OK | AF39: =IF(G39="","-",IF(X39<>"","OK","・上司評価未入力")) -> OK
B40: 信頼構築 | G40: 現場を大切にして、顧客の利益につながるよう、特に指示がなくとも求められている使命を果たすよう行動し、自身への信頼を獲得している | T40: Ⅲ | X40: Ⅴ | AB40: =IF(X40<>"",VLOOKUP(X40,TBL!Q:R,2,0),"") -> 80 | AC40: =IF(AD40<>"","←","") -> ← | AD40: =IF(G40="","",IF(AND(AE40="OK",AF40="OK"),"OK",IF(AE40="OK",AF40,IF(AF40="OK",AE40,AE40&CHAR(10)&AF40)))) -> OK | AE40: =IF(G40="","-",IF(T40<>"","OK","・自己評価未入力")) -> OK | AF40: =IF(G40="","-",IF(X40<>"","OK","・上司評価未入力")) -> OK
B41: サービス改善・創意工夫 | G41: 顧客のより高い満足を実現するために、提供サービスや業務に創意工夫や改善を行ない、チーム全体で顧客の期待以上の品質向上や効率化に取り組んでいる。 | T41: Ⅲ | X41: Ⅳ | AB41: =IF(X41<>"",VLOOKUP(X41,TBL!Q:R,2,0),"") -> 60 | AC41: =IF(AD41<>"","←","") -> ← | AD41: =IF(G41="","",IF(AND(AE41="OK",AF41="OK"),"OK",IF(AE41="OK",AF41,IF(AF41="OK",AE41,AE41&CHAR(10)&AF41)))) -> OK | AE41: =IF(G41="","-",IF(T41<>"","OK","・自己評価未入力")) -> OK | AF41: =IF(G41="","-",IF(X41<>"","OK","・上司評価未入力")) -> OK
A42: 組織に対する期待行動 | B42: 協調・チームワーク | G42: 各人の考えや立場を尊重しながらチームの一員として建設的なコミュニケーションを図りながら、自身の役割を果たすと共に、メンバーが互いに協力し合えるよう、積極的に周囲がサポートしやすい土壌を形成している。 | T42: Ⅲ | U42: XXXXXXXXX | X42: Ⅲ | AB42: =IF(X42<>"",VLOOKUP(X42,TBL!Q:R,2,0),"") -> 40 | AC42: =IF(AD42<>"","←","") -> ← | AD42: =IF(G42="","",IF(AND(AE42="OK",AF42="OK"),"OK",IF(AE42="OK",AF42,IF(AF42="OK",AE42,AE42&CHAR(10)&AF42)))) -> OK | AE42: =IF(G42="","-",IF(T42<>"","OK","・自己評価未入力")) -> OK | AF42: =IF(G42="","-",IF(X42<>"","OK","・上司評価未入力")) -> OK
B43: 役割認識・リーダーシップ | G43: 組織目標や上位方針から、自身の果たすべき役割や責任を正しく認識し、迅速な行動・判断によってリーダーシップを発揮し、チームに貢献している。 | T43: Ⅲ | X43: Ⅲ | AB43: =IF(X43<>"",VLOOKUP(X43,TBL!Q:R,2,0),"") -> 40 | AC43: =IF(AD43<>"","←","") -> ← | AD43: =IF(G43="","",IF(AND(AE43="OK",AF43="OK"),"OK",IF(AE43="OK",AF43,IF(AF43="OK",AE43,AE43&CHAR(10)&AF43)))) -> OK | AE43: =IF(G43="","-",IF(T43<>"","OK","・自己評価未入力")) -> OK | AF43: =IF(G43="","-",IF(X43<>"","OK","・上司評価未入力")) -> OK
B44: 組織･ネットワーク活用 | G44: 自身の領域や能力では足りないものに対し、必要時には周囲や上位者の支援を仰ぎ、社内外の情報リソースや社内の人脈によるネットワーク等も有効活用しながら目標達成に向け取り組んでいる。 | T44: Ⅲ | X44: Ⅲ | AB44: =IF(X44<>"",VLOOKUP(X44,TBL!Q:R,2,0),"") -> 40 | AC44: =IF(AD44<>"","←","") -> ← | AD44: =IF(G44="","",IF(AND(AE44="OK",AF44="OK"),"OK",IF(AE44="OK",AF44,IF(AF44="OK",AE44,AE44&CHAR(10)&AF44)))) -> OK | AE44: =IF(G44="","-",IF(T44<>"","OK","・自己評価未入力")) -> OK | AF44: =IF(G44="","-",IF(X44<>"","OK","・上司評価未入力")) -> OK
B45: 人材育成 | G45: 自身の持つ専門知識やスキル、習得したノウハウや経験を用いて、周囲へのサポートやメンバーへの具体的なアドバイス、業務支援をすることで、業務を通じた育成をサポートしている。 | T45: Ⅲ | X45: Ⅲ | AB45: =IF(X45<>"",VLOOKUP(X45,TBL!Q:R,2,0),"") -> 40 | AC45: =IF(AD45<>"","←","") -> ← | AD45: =IF(G45="","",IF(AND(AE45="OK",AF45="OK"),"OK",IF(AE45="OK",AF45,IF(AF45="OK",AE45,AE45&CHAR(10)&AF45)))) -> OK | AE45: =IF(G45="","-",IF(T45<>"","OK","・自己評価未入力")) -> OK | AF45: =IF(G45="","-",IF(X45<>"","OK","・上司評価未入力")) -> OK
...

Sheet ①行動評価項目
A1: ■行動評価項目
A2: 項目名 | C2: 定義 | D2: 行動評価項目 / 階層別標準行動
D3: メンバー（等級1相当） | E3: リーダー/チーフ/SV（等級2,3相当） | F3: マネージャー（等級4,5相当） | G3: 年俸相当
A4: 事業所のTCIP | B4: T（Trust）信頼 | C4: 常に顧客視点で物事を考え、お客様のニーズを正確に把握し、それを最大限に満たすことを最優先に業務に取り組む。 | D4: - | E4: 通り一辺倒な質疑応答ではなく対話者の状況を正しくヒアリングし、ひとりひとりの状況に合わせた案内を行います | F4: - | G4: -
B5: C（Contribution）貢献 | C5: 理論や知識だけではなく、現場やお客様との直接のコミュニケーションを重視して業務を行い、信頼関係を構築する。 | D5: - | E5: 対話者の方のお困りごとがなぜ起こったのか？を汲み取り改善につながる声を拾います | F5: - | G5: -
B6: I（Improvement）成長 | C6: 常に高い目標を掲げて、新たな仕事や課題に挑戦し、自らが主体となって大きな成果と変革につなげている。 | D6: - | E6: 変化していく環境にあわせプロフェッショナルとして「よりよい案内とは？」を考え成長していきます | F6: - | G6: -
B7: P（People）ヒト | C7: 個人の考えや意見を尊重し、チームメンバーが互いに協力し合えるよう、自ら積極的に周囲をサポートし、他組織との調整においても互いの合意点を導くよう働き掛ける。 | D7: - | E7: 対話者の方への配慮を第一に、わかりやすい速度・表現での案内とともに人ならではの対話を行います | F7: - | G7: -
A8: 変化に対する期待行動 | B8: 情報収集 | C8: 情報リソースやルートを拡げて、必要な情報を幅広く収集し、その有用性を見極めて業務に活用する。 | D8: - | E8: 自部門のサービス・業務に対し、業務レベルでの理解があり、関連する最新の業界動向や顧客情報、競合他社情報などを幅広く収集して、業務に活用している。 | F8: - | G8: -
B9: 課題認識・企画提案 | C9: 常に問題意識を持って、提供するサービスや業務プロセス、現状に対する課題を特定し、その解決・改善に向けた提案を行う。 | D9: - | E9: 業務上の問題点を整理し、状況、状態を的確に把握すると共に、状況変化に応じて業務の優先順位をつけて、対応策を検討している。 | F9: - | G9: -
B10: 適応・柔軟性 | C10: 取り巻く環境や状況の変化、または変化の予兆を正確に把握し、自身の考え方や業務（事業）の方針を柔軟に対応させている。 | D10: - | E10: 環境や状況の変化を察知し、上位方針や過去の事例に基づいて適切に判断している。 | F10: - | G10: -
A11: 顧客に対する期待行動 | B11: 信頼構築 | C11: 理論や知識だけではなく、現場やお客様との直接のコミュニケーションを重視して業務を行い、信頼関係を構築する。 | D11: - | E11: 現場を大切にして、顧客の利益につながるよう、特に指示がなくとも求められている使命を果たすよう行動し、自身への信頼を獲得している | F11: - | G11: -
B12: サービス改善・創意工夫 | C12: お客様のより高い満足を実現するために、常に提供サービスや業務に工夫と改善、新たな提案を行うことで、品質の向上や効率化に取り組む。 | D12: - | E12: 顧客のより高い満足を実現するために、提供サービスや業務に創意工夫や改善を行ない、チーム全体で顧客の期待以上の品質向上や効率化に取り組んでいる。 | F12: - | G12: -
A13: 組織に対する期待行動 | B13: 役割認識・リーダーシップ | C13: 果たすべき役割を正確に認識し、上位方針の実践や組織目標の達成に貢献するよう、自発的・積極的に取り組み、組織の中でリーダーシップを発揮する。 | D13: - | E13: 組織目標や上位方針から、自身の果たすべき役割や責任を正しく認識し、迅速な行動・判断によってリーダーシップを発揮し、チームに貢献している。 | F13: - | G13: -
B14: 組織･ネットワーク活用 | C14: 組織による目標達成を意識し、組織内の適切なリソース配分や社内外のネットワーク・リソースの活用によって、より大きな成果につなげる。 | D14: - | E14: 自身の領域や能力では足りないものに対し、必要時には周囲や上位者の支援を仰ぎ、社内外の情報リソースや社内の人脈によるネットワーク等も有効活用しながら目標達成に向け取り組んでいる。 | F14: - | G14: -
B15: 人材育成 | C15: 成功事例やノウハウの共有、高度な専門知識やスキルの伝授、効果的な育成環境を作ることで、組織全体のスキルの底上げを行なう。 | D15: - | E15: 自身の持つ専門知識やスキル、習得したノウハウや経験を用いて、周囲へのサポートやメンバーへの具体的なアドバイス、業務支援をすることで、業務を通じた育成をサポートしている。 | F15: - | G15: -
A16: プロフェッショナルとしての期待行動 | B16: タスク管理 | C16: 優先順位づけと進捗管理を適切に行うことで、計画的・効率的に業務を遂行する。 | D16: - | E16: 担当する業務において、タスクの優先付けと進捗管理を適切に行い、サービス品質やアウトプット納期を確保している。 | F16: - | G16: -
B17: 達成志向・責任感 | C17: 意欲と粘り強さ、トランスコスモス社員としての誇りと誠実さを持って全力で業務に取り組み、立てた目標や計画を責任を持って成し遂げる。 | D17: - | E17: 目標の見直しが必要な場合は計画の見直しや業務プロセスの改善を取り組み、目標や計画を責任を持って成し遂げている。 | F17: - | G17: -
B18: 自己研鑽 | C18: 常に向上心を持って、必要な知識と専門スキルの習得を行い、自身の付加価値を高めて業務に活用する。 | D18: - | E18: 自らの成長を意識して、役割に応じた目標を設定し取り組むと共に、担当業務に関連する最新知識や専門スキルを継続的に収集・加工・分析・整理し、業務に活用している。 | F18: - | G18: -
B19: ストレスマネジメント | C19: 自身に関わる批判的な意見に対しても、冷静に対処し、職務を完遂する為に必要な考えや前向きな気持ちのもと行動する。 | D19: - | E19: チャレンジングな環境においても冷静な対応を行い、職務を完遂する為に必要な考えや前向きな気持ちで行動している。 | F19: - | G19: -

Sheet TBL
A2: ■等級TBL | D2: ■成果評価TBL | I2: ■行動評価参照 | M2: ■目標カテゴリ | Q2: ■行動評価TBL
A3: 等級 | D3: 難易度 | E3: 達成度 | F3: VLOOK用 | G3: 評価点 | I3: 等級 | J3: 参照列 | M3: 目標区分 | N3: 目標カテゴリ | Q3: 評語 | R3: 得点
A4: 等級1 | D4: S | E4: Ⅴ | F4: =D4&E4 -> SⅤ | G4: 80 | I4: メンバー | J4: 3 | M4: 業績関連目標 | N4: 売上関連 | Q4: Ⅴ | R4: 80
A5: 等級2 | D5: S | E5: Ⅳ | F5: =D5&E5 -> SⅣ | G5: 65 | I5: リーダー/チーフ/SV | J5: 4 | N5: 利益関連 | Q5: Ⅳ | R5: 60
A6: 等級3 | D6: S | E6: Ⅲ | F6: =D6&E6 -> SⅢ | G6: 55 | I6: マネジャー | J6: 5 | N6: その他 | Q6: Ⅲ | R6: 40
A7: 等級4 | D7: S | E7: Ⅱ | F7: =D7&E7 -> SⅡ | G7: 40 | M7: 個人重点施策 | N7: 業務拡大・企画提案 | Q7: Ⅱ | R7: 20
A8: 等級5 | D8: S | E8: Ⅰ | F8: =D8&E8 -> SⅠ | G8: 25 | N8: 業務改善・品質向上 | Q8: Ⅰ | R8: 1
A9: 年俸 | D9: A | E9: Ⅴ | F9: =D9&E9 -> AⅤ | G9: 70 | N9: 業務遂行
D10: A | E10: Ⅳ | F10: =D10&E10 -> AⅣ | G10: 55 | N10: その他
D11: A | E11: Ⅲ | F11: =D11&E11 -> AⅢ | G11: 45 | M11: 人材関連目標 | N11: 職場活性
D12: A | E12: Ⅱ | F12: =D12&E12 -> AⅡ | G12: 30 | N12: 人材育成
D13: A | E13: Ⅰ | F13: =D13&E13 -> AⅠ | G13: 15 | N13: 自己研鑽
D14: B | E14: Ⅴ | F14: =D14&E14 -> BⅤ | G14: 55 | N14: その他
D15: B | E15: Ⅳ | F15: =D15&E15 -> BⅣ | G15: 45
D16: B | E16: Ⅲ | F16: =D16&E16 -> BⅢ | G16: 35
D17: B | E17: Ⅱ | F17: =D17&E17 -> BⅡ | G17: 25
D18: B | E18: Ⅰ | F18: =D18&E18 -> BⅠ | G18: 10
D19: C | E19: Ⅴ | F19: =D19&E19 -> CⅤ | G19: 45
D20: C | E20: Ⅳ | F20: =D20&E20 -> CⅣ | G20: 35
D21: C | E21: Ⅲ | F21: =D21&E21 -> CⅢ | G21: 25
D22: C | E22: Ⅱ | F22: =D22&E22 -> CⅡ | G22: 15
D23: C | E23: Ⅰ | F23: =D23&E23 -> CⅠ | G23: 1
